#### 目录

* 程序错误
* 异常语法
* 异常抛出
* 异常捕获
* 异常传播
* 栈展开

##### 程序错误

* **编译**错误
  * **语法错误**，**不能生成可执行程序**
* **运行时**错误
  * 不可预料的逻辑错误
  * 可以预料的运行异常
    * 动态分配空间时可能不会成功
    * 打开文件可能失败
    * 除法运算分母为0
    * 整数相乘可能溢出
    * 数组越界...

##### 异常语法

* ```c++
  try
  {
      // try语句块                     // throw <表达式>
  }
  catch(类型1 参数1)
  {
      // 针对类型1的异常处理
  }
  catch(类型2 参数2)
  {
      // 针对类型2的异常处理
  }
  ...
  catch(类型n 参数n)
  {
      // 针对类型n的异常处理
  }
  ```

##### 异常抛出

* 抛出内置类型异常、自定义类型异常

* `throw`抛出一个类对象会调用**拷贝构造函数**

* 异常发生之前创建的**局部对象被销毁**，这一过程被称为**栈展开**

* ```c++
  // #include <stdio.h>
  // #include <setjmp.h>
  #include <unistd.h>
  
  #include <iostream>
  using namespace std;
  
  // jmp_buf _buf_;  // 保存当前栈环境的数组
  class MyException
  {
  public:
      MyException(const char* message)
          : message_(message)
      {
          cout<<"MyException..."<<endl;
      }
      MyException(const MyException& other):message_(other.message_)
      {
          cout<<"copy MyException..."<<endl;
      }
      ~MyException()
      {
          cout<<"~MyException"<<endl;
      }
  
      const char* what() const 
      {
          return message_.c_str();
      }
  private:
      string message_;
  };
  
  double Divide(double a,double b)
  {
      if(b==0.0)
      {
          MyException e("division by zero");
          throw(e);    // 抛出整型异常
      } 
      else return a/b;
  }
  
  int main()
  {
      try {
          cout<<Divide(5.0,0.0)<<endl;
      }
      catch(MyException& e)
      {
          cout<<e.what()<<endl;
      }
      return 0;
  }
  // result
  MyException...
  copy MyException...
  ~MyException
  copy MyException...
  division by zero
  ~MyException
  ~MyException
  ```

##### 异常捕获

* 一个异常处理器一般只捕捉一种类型的异常

* 异常处理器的参数类型和抛出异常的类型相同

* `...`表示可以捕获任何异常

  * ```c++
    throw 1;
    catch(int)
    {}
    throw 1.5;
    catch(double)
    {}
    ```

##### `throw MyException("123");`与函数返回对象

* 此时不会调用拷贝构造，而是直接将该对象返回作为返回值对象

  * ```c++
    Test fun()
    {
    	return Test();
    }
    
    int main()
    {
    	fun(); // 没人接收，又被释放了
    }
    ```

##### 异常的传播

* `try`可以嵌套
* 程序顺序寻找匹配的异常处理器，抛出的异常被第一个类型符合的异常处理器捕获
* 若内层的`try`块后面没有找到合适的异常处理器，异常**向外传播**，到**外层`try`块后面的`catch`中寻找**
  * ![image-20220104213342297](%E5%BC%82%E5%B8%B8%E4%B8%8E%E6%A0%88%E5%B1%95%E5%BC%80.assets/image-20220104213342297.png)
* 没有被捕获的异常将调用`terminate`函数，其默认调用`abort`终止程序的执行
  * 直接终止进程
* 可以使用`set_terminate`函数指定`terminate`函数

##### 栈展开

* 沿着嵌套调用链接向上查找，直到为异常找到一个`catch`子句
  * 为局部对象调用析构函数
  * 析构函数不应该抛出异常
    * 栈展开